SID: 8      TIME:2022-10-24 12:02:31.101790 
Traceback (most recent call last):
  File "\\ad.uit.no\uit\data\esi000data\dokumenter\forskning\papers\paneltime\paneltime\paneltime\multi_core.py", line 329, in receive
    return u.load()
EOFError: Ran out of input

During handling of the above exception, another exception occurred:

Traceback (most recent call last):
  File "\\ad.uit.no\uit\data\esi000data\dokumenter\forskning\papers\paneltime\paneltime\paneltime\multi_core_slave.py", line 75, in listen
    callback_class.send_callback(True)
  File "\\ad.uit.no\uit\data\esi000data\dokumenter\forskning\papers\paneltime\paneltime\paneltime\multi_core_slave.py", line 107, in send_callback
    msg, (self.inbox, quit) = self.t.receive()
  File "\\ad.uit.no\uit\data\esi000data\dokumenter\forskning\papers\paneltime\paneltime\paneltime\multi_core.py", line 336, in receive
    raise RuntimeError("""An error occured in one of the spawned sub-processes.
RuntimeError: An error occured in one of the spawned sub-processes. 
Check the output in "slave_errors.txt' in your working directory or 
run without multiprocessing
 2022-10-24 12:02:31.101790

During handling of the above exception, another exception occurred:

Traceback (most recent call last):
  File "\\ad.uit.no\uit\data\esi000data\dokumenter\forskning\papers\paneltime\paneltime\paneltime\multi_core_slave.py", line 145, in <module>
    main(t,initcommand,s_id,fpath)
  File "\\ad.uit.no\uit\data\esi000data\dokumenter\forskning\papers\paneltime\paneltime\paneltime\multi_core_slave.py", line 52, in main
    listen(obj, callback_class, d, f)
  File "\\ad.uit.no\uit\data\esi000data\dokumenter\forskning\papers\paneltime\paneltime\paneltime\multi_core_slave.py", line 79, in listen
    raise RuntimeError(e)
RuntimeError: An error occured in one of the spawned sub-processes. 
Check the output in "slave_errors.txt' in your working directory or 
run without multiprocessing
 2022-10-24 12:02:31.101790
