SID: 5      TIME:2022-08-26 13:45:26.387244 
Traceback (most recent call last):
  File "\\ad.uit.no\uit\data\esi000data\dokumenter\forskning\papers\paneltime\paneltime\paneltime\multi_core.py", line 321, in receive
    return u.load()
EOFError: Ran out of input

During handling of the above exception, another exception occurred:

Traceback (most recent call last):
  File "\\ad.uit.no\uit\data\esi000data\dokumenter\forskning\papers\paneltime\paneltime\paneltime\multi_core_slave.py", line 129, in <module>
    main(t,initcommand,s_id,fpath)
  File "\\ad.uit.no\uit\data\esi000data\dokumenter\forskning\papers\paneltime\paneltime\paneltime\multi_core_slave.py", line 23, in main
    (msg,obj) = t.receive()
  File "\\ad.uit.no\uit\data\esi000data\dokumenter\forskning\papers\paneltime\paneltime\paneltime\multi_core.py", line 328, in receive
    raise RuntimeError("""An error occured in one of the spawned sub-processes.
RuntimeError: An error occured in one of the spawned sub-processes. 
Check the output in "slave_errors.txt' in your working directory or 
run without multiprocessing
 2022-08-26 13:45:26.387244

